<?xml version="1.0" ?>
<!-- =================================================================================== -->
<!-- |    This document was autogenerated by xacro from src/start_creating_robots/worlds_and_models/krytn/krytn.urdf.xacro | -->
<!-- |    EDITING THIS FILE BY HAND IS NOT RECOMMENDED                                 | -->
<!-- =================================================================================== -->
<robot name="krytn">
  <!-- see https://secure.wikimedia.org/wikipedia/en/wiki/List_of_moment_of_inertia_tensors -->
  <link name="base_footprint"/>
  <joint name="base_footprint_joint" type="fixed">
    <parent link="base_footprint"/>
    <child link="base_link"/>
    <origin rpy="0 0 0" xyz="0 0 0.1"/>
  </joint>
  <!-- Base Link -->
  <link name="base_link">
    <origin rpy="0 0 0" xyz="-0.25 0 0.03"/>
    <visual>
      <origin rpy="0 0 0" xyz="-0.11 0 -0.029000000000000012"/>
      <geometry>
        <mesh filename="file:///workspace/install/start_creating_robots/share/start_creating_robots/worlds_and_models/krytn/meshes/magni_body.dae"/>
      </geometry>
    </visual>
    <collision>
      <origin rpy="0 0 0" xyz="-0.11 0 0.05099999999999999"/>
      <geometry>
        <box size="0.398 0.268 0.160"/>
      </geometry>
    </collision>
    <collision>
      <origin rpy="0 0 0" xyz="-0.136 0 0.148"/>
      <geometry>
        <box size="0.375 0.268 0.034"/>
      </geometry>
    </collision>
    <collision>
      <origin rpy="0 0 0" xyz="-0.279 0.169 0.0059999999999999915"/>
      <geometry>
        <box size="0.1 0.07 0.07"/>
      </geometry>
    </collision>
    <collision>
      <origin rpy="0 0 0" xyz="-0.279 -0.169 0.0059999999999999915"/>
      <geometry>
        <box size="0.1 0.07 0.07"/>
      </geometry>
    </collision>
    <inertial>
      <mass value="10.0"/>
      <origin rpy="0 0 0" xyz="-0.15 0 0.03"/>
      <inertia ixx="0.059450809553" ixy="0.0" ixz="0.0" iyy="0.150753273032" iyz="0.0" izz="0.17270409758500002"/>
    </inertial>
  </link>
  <gazebo reference="base_link">
    <mu>0.1</mu>
    <mu1>0.1</mu1>
    <mu2>0.1</mu2>
    <slip1>0</slip1>
    <slip2>0</slip2>
  </gazebo>
  <link name="left_wheel">
    <collision>
      <origin rpy="0 1.5707963267948966 0" xyz="0.033 0 0"/>
      <geometry>
        <cylinder length="0.01" radius="0.1"/>
      </geometry>
    </collision>
    <visual>
      <origin rpy="0 0.0 0" xyz="-0.071 0 0"/>
      <geometry>
        <mesh filename="file:///workspace/install/start_creating_robots/share/start_creating_robots/worlds_and_models/krytn/meshes/front_wheel.dae"/>
      </geometry>
    </visual>
    <inertial>
      <mass value="1.34"/>
      <origin rpy="0 1.5707963267948966 0" xyz="0 0 0"/>
      <inertia ixx="0.003629165215000001" ixy="0.0" ixz="0.0" iyy="0.003629165215000001" iyz="0.0" izz="0.006700000000000001"/>
    </inertial>
  </link>
  <joint name="left_wheel_joint" type="continuous">
    <axis rpy="0 0 0" xyz="1 0 0"/>
    <parent link="base_link"/>
    <child link="left_wheel"/>
    <origin rpy="0 0 1.5707963267948966" xyz="0 0.163 0"/>
    <dynamics damping="0.2" friction="0.8"/>
  </joint>
  <gazebo reference="left_wheel">
    <mu>0.5</mu>
    <mu1>0.5</mu1>
    <mu2>0.5</mu2>
    <minDepth>0.005</minDepth>
    <kp>1e8</kp>
  </gazebo>
  <link name="right_wheel">
    <collision>
      <origin rpy="0 1.5707963267948966 0" xyz="-0.033 0 0"/>
      <geometry>
        <cylinder length="0.01" radius="0.1"/>
      </geometry>
    </collision>
    <visual>
      <origin rpy="0 -3.141592653589793 0" xyz="0.071 0 0"/>
      <geometry>
        <mesh filename="file:///workspace/install/start_creating_robots/share/start_creating_robots/worlds_and_models/krytn/meshes/front_wheel.dae"/>
      </geometry>
    </visual>
    <inertial>
      <mass value="1.34"/>
      <origin rpy="0 1.5707963267948966 0" xyz="0 0 0"/>
      <inertia ixx="0.003629165215000001" ixy="0.0" ixz="0.0" iyy="0.003629165215000001" iyz="0.0" izz="0.006700000000000001"/>
    </inertial>
  </link>
  <joint name="right_wheel_joint" type="continuous">
    <axis rpy="0 0 0" xyz="1 0 0"/>
    <parent link="base_link"/>
    <child link="right_wheel"/>
    <origin rpy="0 0 1.5707963267948966" xyz="0 -0.163 0"/>
    <dynamics damping="0.2" friction="0.8"/>
  </joint>
  <gazebo reference="right_wheel">
    <mu>0.5</mu>
    <mu1>0.5</mu1>
    <mu2>0.5</mu2>
    <minDepth>0.005</minDepth>
    <kp>1e8</kp>
  </gazebo>
  <link name="left_caster_wheel">
    <origin rpy="0 0 0" xyz="-0.37 0.169 -0.060000000000000005"/>
    <collision>
      <origin rpy="0 0 0" xyz="-0.27 0.169 -0.060000000000000005"/>
      <geometry>
        <sphere radius="0.04"/>
      </geometry>
    </collision>
    <visual>
      <origin rpy="0 0 3.141592653589793" xyz="-0.25 0.169 0"/>
      <geometry>
        <mesh filename="file:///workspace/install/start_creating_robots/share/start_creating_robots/worlds_and_models/krytn/meshes/caster_wheel.dae"/>
      </geometry>
    </visual>
    <!-- removing inertia of caster wheels so that base inertial is not tilted. 
      <xacro:cylinder_inertial_with_origin radius="${wheel_r}" length="0.05" mass="3.34">
          <origin xyz="0 0 0" rpy="0 ${pi/2} 0" />
       </xacro:cylinder_inertial_with_origin> 
       -->
  </link>
  <joint name="left_caster_wheel_joint" type="fixed">
    <parent link="base_link"/>
    <child link="left_caster_wheel"/>
  </joint>
  <gazebo reference="left_caster_wheel">
    <mu>0.1</mu>
    <mu1>0.1</mu1>
    <mu2>0.1</mu2>
    <slip1>0</slip1>
    <slip2>0</slip2>
  </gazebo>
  <link name="right_caster_wheel">
    <origin rpy="0 0 0" xyz="-0.37 -0.169 -0.060000000000000005"/>
    <collision>
      <origin rpy="0 0 0" xyz="-0.27 -0.169 -0.060000000000000005"/>
      <geometry>
        <sphere radius="0.04"/>
      </geometry>
    </collision>
    <visual>
      <origin rpy="0 0 3.141592653589793" xyz="-0.25 -0.169 0"/>
      <geometry>
        <mesh filename="file:///workspace/install/start_creating_robots/share/start_creating_robots/worlds_and_models/krytn/meshes/caster_wheel.dae"/>
      </geometry>
    </visual>
    <!-- removing inertia of caster wheels so that base inertial is not tilted. 
      <xacro:cylinder_inertial_with_origin radius="${wheel_r}" length="0.05" mass="3.34">
          <origin xyz="0 0 0" rpy="0 ${pi/2} 0" />
       </xacro:cylinder_inertial_with_origin> 
       -->
  </link>
  <joint name="right_caster_wheel_joint" type="fixed">
    <parent link="base_link"/>
    <child link="right_caster_wheel"/>
  </joint>
  <gazebo reference="right_caster_wheel">
    <mu>0.1</mu>
    <mu1>0.1</mu1>
    <mu2>0.1</mu2>
    <slip1>0</slip1>
    <slip2>0</slip2>
  </gazebo>
  <link name="lidar_2d_v1">
    <origin rpy="0 0 0" xyz="0.1 0 0.36"/>
    <inertial>
      <mass value="0.13"/>
      <origin rpy="0 1.5707963267948966 0" xyz="0 0 0.03"/>
      <inertia ixx="0.0013400827973" ixy="0.0" ixz="0.0" iyy="0.0013400827973" iyz="0.0" izz="2.6000000000000005e-05"/>
    </inertial>
    <collision name="collision_base">
      <pose>0 0 0.0175015175 0 0 0</pose>
      <geometry>
        <box size="0.05001062 0.05001062 0.035003035"/>
      </geometry>
    </collision>
    <collision name="collision_top">
      <pose>0 0 0.0525045525 0 0 0</pose>
      <geometry>
        <cylinder length="0.035003035" radius="0.02"/>
      </geometry>
    </collision>
    <visual name="visual">
      <pose>0 0 0 0 0 1.5707</pose>
      <geometry>
        <mesh filename="file:///workspace/install/start_creating_robots/share/start_creating_robots/worlds_and_models/krytn//meshes/lidar_2d_v1.dae"/>
      </geometry>
    </visual>
  </link>
  <!-- This joint connects the robot to the lidar -->
  <joint name="lidar_joint" type="fixed">
    <parent link="base_footprint"/>
    <child link="lidar_2d_v1"/>
    <origin rpy="0 0 0" xyz="-0.1 0 0.268"/>
  </joint>
  <gazebo reference="lidar_2d_v1">
    <sensor name="lidar_2d_v1" type="gpu_ray">
      <topic>lidar</topic>
      <ignition_frame_id>lidar_2d_v1</ignition_frame_id>
      <pose>0 0 0.0525045525 0 0 0</pose>
      <ray>
        <scan>
          <horizontal>
            <samples>90</samples>
            <resolution>1</resolution>
            <min_angle>-1.41</min_angle>
            <max_angle>1.41</max_angle>
          </horizontal>
        </scan>
        <range>
          <min>0.060</min>
          <max>10</max>
          <resolution>0.04</resolution>
        </range>
        <noise>
          <type>gaussian</type>
          <mean>0.0</mean>
          <stddev>0.001</stddev>
        </noise>
      </ray>
      <always_on>0</always_on>
      <update_rate>20</update_rate>
      <visualize>false</visualize>
    </sensor>
  </gazebo>
  <link name="realsense_d435">
    <origin rpy="0 0 0" xyz="0.2 0 0.2"/>
    <collision name="collision">
      <geometry>
        <mesh filename="file:///workspace/install/start_creating_robots/share/start_creating_robots/worlds_and_models/krytn/meshes/realsense.dae"/>
      </geometry>
    </collision>
    <visual name="visual">
      <geometry>
        <mesh filename="file:///workspace/install/start_creating_robots/share/start_creating_robots/worlds_and_models/krytn/meshes/realsense.dae">
          <submesh>
            <name>RealSense</name>
            <center>false</center>
          </submesh>
        </mesh>
      </geometry>
    </visual>
  </link>
  <joint name="depth_camera_joint" type="fixed">
    <parent link="base_footprint"/>
    <child link="realsense_d435"/>
    <origin rpy="0 0 0" xyz="0 0 0.6"/>
  </joint>
  <gazebo reference="realsense_d435">
    <sensor name="realsense_d435" type="rgbd_camera">
      <topic>realsense</topic>
      <ignition_frame_id>realsense_d435</ignition_frame_id>
      <update_rate>5</update_rate>
      <camera name="camera">
        <horizontal_fov>0.5</horizontal_fov>
        <lens>
          <intrinsics>
            <!-- fx = fy = width / ( 2 * tan (hfov / 2 ) ) -->
            <fx>554.25469</fx>
            <fy>554.25469</fy>
            <!-- cx = ( width + 1 ) / 2 -->
            <cx>320.5</cx>
            <!-- cy = ( height + 1 ) / 2 -->
            <cy>240.5</cy>
            <s>0</s>
          </intrinsics>
        </lens>
        <distortion>
          <k1>0.0</k1>
          <k2>0.0</k2>
          <k3>0.0</k3>
          <p1>0.0</p1>
          <p2>0.0</p2>
          <center>0.5 0.5</center>
        </distortion>
        <image>
          <width>160</width>
          <height>120</height>
          <format>R8G8B8</format>
        </image>
        <clip>
          <near>0.01</near>
          <far>10</far>
        </clip>
        <depth_camera>
          <clip>
            <near>0.1</near>
            <far>10</far>
          </clip>
        </depth_camera>
        <noise>
          <type>gaussian</type>
          <mean>0</mean>
          <stddev>0.007</stddev>
        </noise>
      </camera>
    </sensor>
  </gazebo>
  <!-- Coffee Holder Top -->
  <link name="krytn_top">
    <visual name="visual">
      <geometry>
        <mesh filename="file:///workspace/install/start_creating_robots/share/start_creating_robots/worlds_and_models/krytn/meshes/krytn_coffee_top.dae"/>
      </geometry>
    </visual>
  </link>
  <joint class="krytn_top_joint" type="fixed">
    <parent link="base_footprint"/>
    <child link="krytn_top"/>
    <origin rpy="0 0 1.57" xyz="0.05 0 0.26"/>
  </joint>
  <!-- Gazebo specific plugins-->
  <gazebo>
    <plugin filename="ignition-gazebo-sensors-system" name="ignition::gazebo::systems::Sensors">
      <render_engine>ogre2</render_engine>
    </plugin>
    <!-- Publish joints for robot description tf publisher. -->
    <plugin filename="ignition-gazebo-joint-state-publisher-system" name="ignition::gazebo::systems::JointStatePublisher">
      <topic>joint_states</topic>
    </plugin>
    <!-- Plugin to allow Gazebo to recieve cmd_vel and rotate wheels in Gazebo. -->
    <plugin filename="ignition-gazebo-diff-drive-system" name="ignition::gazebo::systems::DiffDrive">
      <left_joint>left_wheel_joint</left_joint>
      <right_joint>right_wheel_joint</right_joint>
      <frame_id>odom</frame_id>
      <wheel_separation>0.326</wheel_separation>
      <wheel_radius>0.128</wheel_radius>
      <odom_publish_frequency>20</odom_publish_frequency>
      <max_linear_acceleration>1</max_linear_acceleration>
      <min_linear_acceleration>-1</min_linear_acceleration>
      <max_angular_acceleration>2</max_angular_acceleration>
      <min_angular_acceleration>-2</min_angular_acceleration>
      <max_linear_velocity>0.5</max_linear_velocity>
      <min_linear_velocity>-0.5</min_linear_velocity>
      <max_angular_velocity>1</max_angular_velocity>
      <min_angular_velocity>-1</min_angular_velocity>
    </plugin>
  </gazebo>
</robot>
